Traceback (most recent call last):
  File "/opt/hostedtoolcache/Python/3.12.5/x64/lib/python3.12/site-packages/jupyter_cache/executors/utils.py", line 58, in single_nb_execution
    executenb(
  File "/opt/hostedtoolcache/Python/3.12.5/x64/lib/python3.12/site-packages/nbclient/client.py", line 1314, in execute
    return NotebookClient(nb=nb, resources=resources, km=km, **kwargs).execute()
           ^^^^^^^^^^^^^^^^^^^^^^^^^^^^^^^^^^^^^^^^^^^^^^^^^^^^^^^^^^^^^^^^^^^^^
  File "/opt/hostedtoolcache/Python/3.12.5/x64/lib/python3.12/site-packages/jupyter_core/utils/__init__.py", line 165, in wrapped
    return loop.run_until_complete(inner)
           ^^^^^^^^^^^^^^^^^^^^^^^^^^^^^^
  File "/opt/hostedtoolcache/Python/3.12.5/x64/lib/python3.12/asyncio/base_events.py", line 687, in run_until_complete
    return future.result()
           ^^^^^^^^^^^^^^^
  File "/opt/hostedtoolcache/Python/3.12.5/x64/lib/python3.12/site-packages/nbclient/client.py", line 709, in async_execute
    await self.async_execute_cell(
  File "/opt/hostedtoolcache/Python/3.12.5/x64/lib/python3.12/site-packages/nbclient/client.py", line 1062, in async_execute_cell
    await self._check_raise_for_error(cell, cell_index, exec_reply)
  File "/opt/hostedtoolcache/Python/3.12.5/x64/lib/python3.12/site-packages/nbclient/client.py", line 918, in _check_raise_for_error
    raise CellExecutionError.from_cell_and_msg(cell, exec_reply_content)
nbclient.exceptions.CellExecutionError: An error occurred while executing the following cell:
------------------
import numpy as np
from graspologic.simulations import sbm
from graphbook_code import dcsbm

np.random.seed(2)

# the block matrix for the neurons before learning
B0 = 0.05*np.ones((3, 3))
np.fill_diagonal(B0, 0.4)

nk = 40
ns = np.repeat(nk, 3)

theta = np.tile(np.linspace(np.sqrt(2), np.sqrt(2) - 1, nk), 3)
zs = np.repeat([1,2,3], nk)

T = 12
networks = np.array([sbm(ns, B0) if (t < 6 or t >= 9) else dcsbm(zs, theta, B0) for t in range(T)])
------------------

----- stderr -----
/opt/hostedtoolcache/Python/3.12.5/x64/lib/python3.12/site-packages/tqdm/auto.py:21: TqdmWarning: IProgress not found. Please update jupyter and ipywidgets. See https://ipywidgets.readthedocs.io/en/stable/user_install.html
  from .autonotebook import tqdm as notebook_tqdm
------------------

[0;31m---------------------------------------------------------------------------[0m
[0;31mNameError[0m                                 Traceback (most recent call last)
Cell [0;32mIn[2], line 18[0m
[1;32m     15[0m zs [38;5;241m=[39m np[38;5;241m.[39mrepeat([[38;5;241m1[39m,[38;5;241m2[39m,[38;5;241m3[39m], nk)
[1;32m     17[0m T [38;5;241m=[39m [38;5;241m12[39m
[0;32m---> 18[0m networks [38;5;241m=[39m np[38;5;241m.[39marray([sbm(ns, B0) [38;5;28;01mif[39;00m (t [38;5;241m<[39m [38;5;241m6[39m [38;5;129;01mor[39;00m t [38;5;241m>[39m[38;5;241m=[39m [38;5;241m9[39m) [38;5;28;01melse[39;00m [43mdcsbm[49m[43m([49m[43mzs[49m[43m,[49m[43m [49m[43mtheta[49m[43m,[49m[43m [49m[43mB0[49m[43m)[49m [38;5;28;01mfor[39;00m t [38;5;129;01min[39;00m [38;5;28mrange[39m(T)])

File [0;32m/opt/hostedtoolcache/Python/3.12.5/x64/lib/python3.12/site-packages/graphbook_code/sbm.py:54[0m, in [0;36mdcsbm[0;34m(z, theta, B, directed, loops, return_prob)[0m
[1;32m     50[0m [38;5;250m[39m[38;5;124;03m"""[39;00m
[1;32m     51[0m [38;5;124;03mA function to sample a DCSBM.[39;00m
[1;32m     52[0m [38;5;124;03m"""[39;00m
[1;32m     53[0m P [38;5;241m=[39m generate_dcsbm_pmtx(z, theta, B)
[0;32m---> 54[0m robj [38;5;241m=[39m [43msample_edges[49m(P, directed[38;5;241m=[39mdirected, loops[38;5;241m=[39mloops)
[1;32m     55[0m [38;5;28;01mif[39;00m return_prob:
[1;32m     56[0m     robj [38;5;241m=[39m (robj, P)

[0;31mNameError[0m: name 'sample_edges' is not defined

