Traceback (most recent call last):
  File "/opt/hostedtoolcache/Python/3.12.5/x64/lib/python3.12/site-packages/jupyter_cache/executors/utils.py", line 58, in single_nb_execution
    executenb(
  File "/opt/hostedtoolcache/Python/3.12.5/x64/lib/python3.12/site-packages/nbclient/client.py", line 1314, in execute
    return NotebookClient(nb=nb, resources=resources, km=km, **kwargs).execute()
           ^^^^^^^^^^^^^^^^^^^^^^^^^^^^^^^^^^^^^^^^^^^^^^^^^^^^^^^^^^^^^^^^^^^^^
  File "/opt/hostedtoolcache/Python/3.12.5/x64/lib/python3.12/site-packages/jupyter_core/utils/__init__.py", line 165, in wrapped
    return loop.run_until_complete(inner)
           ^^^^^^^^^^^^^^^^^^^^^^^^^^^^^^
  File "/opt/hostedtoolcache/Python/3.12.5/x64/lib/python3.12/asyncio/base_events.py", line 687, in run_until_complete
    return future.result()
           ^^^^^^^^^^^^^^^
  File "/opt/hostedtoolcache/Python/3.12.5/x64/lib/python3.12/site-packages/nbclient/client.py", line 709, in async_execute
    await self.async_execute_cell(
  File "/opt/hostedtoolcache/Python/3.12.5/x64/lib/python3.12/site-packages/nbclient/client.py", line 1062, in async_execute_cell
    await self._check_raise_for_error(cell, cell_index, exec_reply)
  File "/opt/hostedtoolcache/Python/3.12.5/x64/lib/python3.12/site-packages/nbclient/client.py", line 918, in _check_raise_for_error
    raise CellExecutionError.from_cell_and_msg(cell, exec_reply_content)
nbclient.exceptions.CellExecutionError: An error occurred while executing the following cell:
------------------
from pandas import DataFrame

ns = [8, 16, 32, 64, 128]
nsims = 200
p = 0.4

results = []
for n in ns:
    for i in range(0, nsims):
        A = gp.simulations.er_np(n, p, directed=False, loops=False)
        phatni = gp.models.EREstimator(directed=False, loops=False).fit(A).p_
        results.append({"n": n, "i": i, "phat": phatni})

res_df = DataFrame(results)
res_df["diff"] = np.abs(res_df["phat"] - p)
------------------


[0;31m---------------------------------------------------------------------------[0m
[0;31mNameError[0m                                 Traceback (most recent call last)
Cell [0;32mIn[8], line 10[0m
[1;32m      8[0m [38;5;28;01mfor[39;00m n [38;5;129;01min[39;00m ns:
[1;32m      9[0m     [38;5;28;01mfor[39;00m i [38;5;129;01min[39;00m [38;5;28mrange[39m([38;5;241m0[39m, nsims):
[0;32m---> 10[0m         A [38;5;241m=[39m [43mgp[49m[38;5;241m.[39msimulations[38;5;241m.[39mer_np(n, p, directed[38;5;241m=[39m[38;5;28;01mFalse[39;00m, loops[38;5;241m=[39m[38;5;28;01mFalse[39;00m)
[1;32m     11[0m         phatni [38;5;241m=[39m gp[38;5;241m.[39mmodels[38;5;241m.[39mEREstimator(directed[38;5;241m=[39m[38;5;28;01mFalse[39;00m, loops[38;5;241m=[39m[38;5;28;01mFalse[39;00m)[38;5;241m.[39mfit(A)[38;5;241m.[39mp_
[1;32m     12[0m         results[38;5;241m.[39mappend({[38;5;124m"[39m[38;5;124mn[39m[38;5;124m"[39m: n, [38;5;124m"[39m[38;5;124mi[39m[38;5;124m"[39m: i, [38;5;124m"[39m[38;5;124mphat[39m[38;5;124m"[39m: phatni})

[0;31mNameError[0m: name 'gp' is not defined

