Traceback (most recent call last):
  File "/opt/hostedtoolcache/Python/3.12.9/x64/lib/python3.12/site-packages/jupyter_cache/executors/utils.py", line 58, in single_nb_execution
    executenb(
  File "/opt/hostedtoolcache/Python/3.12.9/x64/lib/python3.12/site-packages/nbclient/client.py", line 1319, in execute
    return NotebookClient(nb=nb, resources=resources, km=km, **kwargs).execute()
           ^^^^^^^^^^^^^^^^^^^^^^^^^^^^^^^^^^^^^^^^^^^^^^^^^^^^^^^^^^^^^^^^^^^^^
  File "/opt/hostedtoolcache/Python/3.12.9/x64/lib/python3.12/site-packages/jupyter_core/utils/__init__.py", line 165, in wrapped
    return loop.run_until_complete(inner)
           ^^^^^^^^^^^^^^^^^^^^^^^^^^^^^^
  File "/opt/hostedtoolcache/Python/3.12.9/x64/lib/python3.12/asyncio/base_events.py", line 691, in run_until_complete
    return future.result()
           ^^^^^^^^^^^^^^^
  File "/opt/hostedtoolcache/Python/3.12.9/x64/lib/python3.12/site-packages/nbclient/client.py", line 709, in async_execute
    await self.async_execute_cell(
  File "/opt/hostedtoolcache/Python/3.12.9/x64/lib/python3.12/site-packages/nbclient/client.py", line 1062, in async_execute_cell
    await self._check_raise_for_error(cell, cell_index, exec_reply)
  File "/opt/hostedtoolcache/Python/3.12.9/x64/lib/python3.12/site-packages/nbclient/client.py", line 918, in _check_raise_for_error
    raise CellExecutionError.from_cell_and_msg(cell, exec_reply_content)
nbclient.exceptions.CellExecutionError: An error occurred while executing the following cell:
------------------
from graspologic.cluster import AutoGMMCluster

labels = AutoGMMCluster(max_components=10, random_state=0).fit_predict(embedding)
fig = pairplot(embedding, labels=labels, title="(B) AutoGMM Clustering, automatic selection", 
                  legend_name="Predicted Clusters", palette=sns.color_palette("colorblind", 10))

fig.tight_layout()

fname = "pairplot_impute1"
if mode != "png":
    fig.savefig(f"Figures/{mode:s}/{fname:s}.{mode:s}")

fig.savefig(f"Figures/png/{fname:s}.png")
------------------


[31m---------------------------------------------------------------------------[39m
[31mNameError[39m                                 Traceback (most recent call last)
[36mCell[39m[36m [39m[32mIn[10][39m[32m, line 5[39m
[32m      1[39m [38;5;28;01mfrom[39;00m[38;5;250m [39m[34;01mgraspologic[39;00m[34;01m.[39;00m[34;01mcluster[39;00m[38;5;250m [39m[38;5;28;01mimport[39;00m AutoGMMCluster
[32m      3[39m labels = AutoGMMCluster(max_components=[32m10[39m, random_state=[32m0[39m).fit_predict(embedding)
[32m      4[39m fig = pairplot(embedding, labels=labels, title=[33m"[39m[33m(B) AutoGMM Clustering, automatic selection[39m[33m"[39m, 
[32m----> [39m[32m5[39m                   legend_name=[33m"[39m[33mPredicted Clusters[39m[33m"[39m, palette=[43msns[49m.color_palette([33m"[39m[33mcolorblind[39m[33m"[39m, [32m10[39m))
[32m      7[39m fig.tight_layout()
[32m      9[39m fname = [33m"[39m[33mpairplot_impute1[39m[33m"[39m

[31mNameError[39m: name 'sns' is not defined

