Traceback (most recent call last):
  File "/opt/hostedtoolcache/Python/3.12.9/x64/lib/python3.12/site-packages/jupyter_cache/executors/utils.py", line 58, in single_nb_execution
    executenb(
  File "/opt/hostedtoolcache/Python/3.12.9/x64/lib/python3.12/site-packages/nbclient/client.py", line 1319, in execute
    return NotebookClient(nb=nb, resources=resources, km=km, **kwargs).execute()
           ^^^^^^^^^^^^^^^^^^^^^^^^^^^^^^^^^^^^^^^^^^^^^^^^^^^^^^^^^^^^^^^^^^^^^
  File "/opt/hostedtoolcache/Python/3.12.9/x64/lib/python3.12/site-packages/jupyter_core/utils/__init__.py", line 165, in wrapped
    return loop.run_until_complete(inner)
           ^^^^^^^^^^^^^^^^^^^^^^^^^^^^^^
  File "/opt/hostedtoolcache/Python/3.12.9/x64/lib/python3.12/asyncio/base_events.py", line 691, in run_until_complete
    return future.result()
           ^^^^^^^^^^^^^^^
  File "/opt/hostedtoolcache/Python/3.12.9/x64/lib/python3.12/site-packages/nbclient/client.py", line 709, in async_execute
    await self.async_execute_cell(
  File "/opt/hostedtoolcache/Python/3.12.9/x64/lib/python3.12/site-packages/nbclient/client.py", line 1062, in async_execute_cell
    await self._check_raise_for_error(cell, cell_index, exec_reply)
  File "/opt/hostedtoolcache/Python/3.12.9/x64/lib/python3.12/site-packages/nbclient/client.py", line 918, in _check_raise_for_error
    raise CellExecutionError.from_cell_and_msg(cell, exec_reply_content)
nbclient.exceptions.CellExecutionError: An error occurred while executing the following cell:
------------------
from graspologic.inference import latent_position_test

nreps = 1000 # the number of null replicates
lpt = latent_position_test(A_human, A_alien, n_bootstraps = nreps, n_components=d, random_state=0, workers=-1)
print("estimate of p-value: {:.5f}".format(lpt[1]))
# estimate of p-value: 0.00100
------------------


[31m---------------------------------------------------------------------------[39m
[31mTypeError[39m                                 Traceback (most recent call last)
[36mCell[39m[36m [39m[32mIn[10][39m[32m, line 4[39m
[32m      1[39m [38;5;28;01mfrom[39;00m[38;5;250m [39m[34;01mgraspologic[39;00m[34;01m.[39;00m[34;01minference[39;00m[38;5;250m [39m[38;5;28;01mimport[39;00m latent_position_test
[32m      3[39m nreps = [32m1000[39m [38;5;66;03m# the number of null replicates[39;00m
[32m----> [39m[32m4[39m lpt = [43mlatent_position_test[49m[43m([49m[43mA_human[49m[43m,[49m[43m [49m[43mA_alien[49m[43m,[49m[43m [49m[43mn_bootstraps[49m[43m [49m[43m=[49m[43m [49m[43mnreps[49m[43m,[49m[43m [49m[43mn_components[49m[43m=[49m[43md[49m[43m,[49m[43m [49m[43mrandom_state[49m[43m=[49m[32;43m0[39;49m[43m,[49m[43m [49m[43mworkers[49m[43m=[49m[43m-[49m[32;43m1[39;49m[43m)[49m
[32m      5[39m [38;5;28mprint[39m([33m"[39m[33mestimate of p-value: [39m[38;5;132;01m{:.5f}[39;00m[33m"[39m.format(lpt[[32m1[39m]))
[32m      6[39m [38;5;66;03m# estimate of p-value: 0.00100[39;00m

[31mTypeError[39m: latent_position_test() got an unexpected keyword argument 'random_state'

