Traceback (most recent call last):
  File "/opt/hostedtoolcache/Python/3.12.5/x64/lib/python3.12/site-packages/jupyter_cache/executors/utils.py", line 58, in single_nb_execution
    executenb(
  File "/opt/hostedtoolcache/Python/3.12.5/x64/lib/python3.12/site-packages/nbclient/client.py", line 1314, in execute
    return NotebookClient(nb=nb, resources=resources, km=km, **kwargs).execute()
           ^^^^^^^^^^^^^^^^^^^^^^^^^^^^^^^^^^^^^^^^^^^^^^^^^^^^^^^^^^^^^^^^^^^^^
  File "/opt/hostedtoolcache/Python/3.12.5/x64/lib/python3.12/site-packages/jupyter_core/utils/__init__.py", line 165, in wrapped
    return loop.run_until_complete(inner)
           ^^^^^^^^^^^^^^^^^^^^^^^^^^^^^^
  File "/opt/hostedtoolcache/Python/3.12.5/x64/lib/python3.12/asyncio/base_events.py", line 687, in run_until_complete
    return future.result()
           ^^^^^^^^^^^^^^^
  File "/opt/hostedtoolcache/Python/3.12.5/x64/lib/python3.12/site-packages/nbclient/client.py", line 709, in async_execute
    await self.async_execute_cell(
  File "/opt/hostedtoolcache/Python/3.12.5/x64/lib/python3.12/site-packages/nbclient/client.py", line 1062, in async_execute_cell
    await self._check_raise_for_error(cell, cell_index, exec_reply)
  File "/opt/hostedtoolcache/Python/3.12.5/x64/lib/python3.12/site-packages/nbclient/client.py", line 918, in _check_raise_for_error
    raise CellExecutionError.from_cell_and_msg(cell, exec_reply_content)
nbclient.exceptions.CellExecutionError: An error occurred while executing the following cell:
------------------
fig = pairplot(Xhat_perm, labels=zperm, legend_name = "Community",
             title=r"Pairs plot of $\widehat X$ with community annotation",
             dig_kind="hist")
------------------


[0;31m---------------------------------------------------------------------------[0m
[0;31mTypeError[0m                                 Traceback (most recent call last)
Cell [0;32mIn[11], line 1[0m
[0;32m----> 1[0m fig [38;5;241m=[39m [43mpairplot[49m[43m([49m[43mXhat_perm[49m[43m,[49m[43m [49m[43mlabels[49m[38;5;241;43m=[39;49m[43mzperm[49m[43m,[49m[43m [49m[43mlegend_name[49m[43m [49m[38;5;241;43m=[39;49m[43m [49m[38;5;124;43m"[39;49m[38;5;124;43mCommunity[39;49m[38;5;124;43m"[39;49m[43m,[49m
[1;32m      2[0m [43m             [49m[43mtitle[49m[38;5;241;43m=[39;49m[38;5;124;43mr[39;49m[38;5;124;43m"[39;49m[38;5;124;43mPairs plot of $[39;49m[38;5;124;43m\[39;49m[38;5;124;43mwidehat X$ with community annotation[39;49m[38;5;124;43m"[39;49m[43m,[49m
[1;32m      3[0m [43m             [49m[43mdig_kind[49m[38;5;241;43m=[39;49m[38;5;124;43m"[39;49m[38;5;124;43mhist[39;49m[38;5;124;43m"[39;49m[43m)[49m

[0;31mTypeError[0m: pairplot() got an unexpected keyword argument 'dig_kind'

